<robot name="robozero">
    <!--Links Declaration-->
    <link name="base_footprint"/>
    <!--body links       x2-->
    <link name="link23">
        <visual>
            <geometry>
                <box size="0.0358 0.0196 0.025"/>
            </geometry>
            <origin xyz="0 -0.009 -0.01" rpy="1.57 0 1.57"/>
        </visual>
        <collision>
            <geometry>
                <box size="0.0358 0.0196 0.025"/>
            </geometry>
            <origin xyz="0 -0.009 -0.01" rpy="1.57 0 1.57"/>
        </collision>
    </link>
    <link name="link23F"/>
    <link name="link24">
        <visual>
            <geometry>
                <box size="0.0358 0.0196 0.025"/>
            </geometry>
            <origin xyz="0 -0.009 0.015" rpy="0 0 1.57"/>
        </visual>
        <collision>
            <geometry>
                <box size="0.0358 0.0196 0.025"/>
            </geometry>
            <origin xyz="0 -0.009 0.015" rpy="0 0 1.57"/>
        </collision>
    </link>
    <!--right Arm links  x5-->
    <link name="link13">
        <visual>
            <geometry>
                <box size="0.0358 0.0196 0.025"/>
            </geometry>
            <origin xyz="0 0 -0.012" rpy="0 1.57 1.57"/>
        </visual>
        <collision>
            <geometry>
                <box size="0.0358 0.0196 0.025"/>
            </geometry>
            <origin xyz="0 0 -0.012" rpy="0 1.57 1.57"/>
        </collision>
    </link>
    <link name="link14">
        <visual>
            <geometry>
                <box size="0.0358 0.0196 0.025"/>
            </geometry>
            <origin xyz="0.01 0 0.001" rpy="1.57 0 0"/>
        </visual>
        <collision>
            <geometry>
                <box size="0.0358 0.0196 0.025"/>
            </geometry>
            <origin xyz="0.01 0 0.001" rpy="1.57 0 0"/>
        </collision>
    </link>
    <link name="link14F"/>
    <link name="link15">
        <visual>
            <geometry>
                <box size="0.0358 0.0196 0.025"/>
            </geometry>
            <origin xyz="0.01 0 -0.013" rpy="0 0 0"/>
        </visual>
        <collision>
            <geometry>
                <box size="0.0358 0.0196 0.025"/>
            </geometry>
            <origin xyz="0.01 0 -0.013" rpy="0 0 0"/>
        </collision>
    </link>
    <link name="link16">
        <visual>
            <geometry>
                <box size="0.0358 0.0196 0.025"/>
            </geometry>
            <origin xyz="0.01 0 0" rpy="1.57 0 0"/>
        </visual>
        <collision>
            <geometry>
                <box size="0.0358 0.0196 0.025"/>
            </geometry>
            <origin xyz="0.01 0 0" rpy="1.57 0 0"/>
        </collision>
    </link>
    <link name="link16F"/>
    <link name="link17">
        <visual>
            <geometry>
                <box size="0.0358 0.0196 0.025"/>
            </geometry>
            <origin xyz="0.01 -0.009 0" rpy="1.57 0 1.57"/>
        </visual>
        <collision>
            <geometry>
                <box size="0.0358 0.0196 0.025"/>
            </geometry>
            <origin xyz="0.01 -0.009 0" rpy="1.57 0 1.57"/>
        </collision>
    </link>
    <!--left  Arm links  x5-->
    <link name="link18">
        <visual>
            <geometry>
                <box size="0.0358 0.0196 0.025"/>
            </geometry>
            <origin xyz="0 0 -0.012" rpy="0 1.57 1.57"/>
        </visual>
        <collision>
            <geometry>
                <box size="0.0358 0.0196 0.025"/>
            </geometry>
            <origin xyz="0 0 -0.012" rpy="0 1.57 1.57"/>
        </collision>
    </link>
    <link name="link19">
        <visual>
            <geometry>
                <box size="0.0358 0.0196 0.025"/>
            </geometry>
            <origin xyz="-0.01 0 0.001" rpy="1.57 0 0"/>
        </visual>
        <collision>
            <geometry>
                <box size="0.0358 0.0196 0.025"/>
            </geometry>
            <origin xyz="-0.01 0 -0.001" rpy="1.57 0 0"/>
        </collision>
    </link>
    <link name="link19F"/>
    <link name="link20">
        <visual>
            <geometry>
                <box size="0.0358 0.0196 0.025"/>
            </geometry>
            <origin xyz="-0.01 0 -0.013" rpy="0 0 0"/>
        </visual>
        <collision>
            <geometry>
                <box size="0.0358 0.0196 0.025"/>
            </geometry>
            <origin xyz="-0.01 0 -0.013" rpy="0 0 0"/>
        </collision>
    </link>
    <link name="link21">
        <visual>
            <geometry>
                <box size="0.0358 0.0196 0.025"/>
            </geometry>
            <origin xyz="-0.01 0 0" rpy="1.57 0 0"/>
        </visual>
        <collision>
            <geometry>
                <box size="0.0358 0.0196 0.025"/>
            </geometry>
            <origin xyz="-0.01 0 0" rpy="1.57 0 0"/>
        </collision>
    </link>
    <link name="link21F"/>
    <link name="link22">
        <visual>
            <geometry>
                <box size="0.0358 0.0196 0.025"/>
            </geometry>
            <origin xyz="-0.01 -0.009 0" rpy="1.57 0 1.57"/>
        </visual>
        <collision>
            <geometry>
                <box size="0.0358 0.0196 0.025"/>
            </geometry>
            <origin xyz="-0.01 -0.009 0" rpy="1.57 0 1.57"/>
        </collision>
    </link>
    <!--right Leg links  x6-->
    <link name="link01">
        <visual>
            <geometry>
                <box size="0.0358 0.0196 0.025"/>
            </geometry>
            <origin xyz="0 0 -0.01" rpy="0 1.57 1.57"/>
        </visual>
        <collision>
            <geometry>
                <box size="0.0358 0.0196 0.025"/>
            </geometry>
            <origin xyz="0 0 -0.01" rpy="0 1.57 1.57"/>
        </collision>
    </link>
    <link name="link01F"/>
    <link name="link02">
        <visual>
            <geometry>
                <box size="0.0358 0.0196 0.025"/>
            </geometry>
            <origin xyz="0 0 -0.02" rpy="1.57 1.57 1.57"/>
        </visual>
        <collision>
            <geometry>
                <box size="0.0358 0.0196 0.025"/>
            </geometry>
            <origin xyz="0 0 -0.02" rpy="1.57 1.57 1.57"/>
        </collision>
    </link>
    <link name="link03">
        <visual>
            <geometry>
                <box size="0.0358 0.0196 0.025"/>
            </geometry>
            <origin xyz="0 0 -0.012" rpy="1.57 1.57 1.57"/>
        </visual>
        <collision>
            <geometry>
                <box size="0.0358 0.0196 0.025"/>
            </geometry>
            <origin xyz="0 0 -0.012" rpy="1.57 1.57 1.57"/>
        </collision>
    </link>
    <link name="link03F"/>
    <link name="link04">
        <visual>
            <geometry>
                <box size="0.0358 0.0196 0.025"/>
            </geometry>
            <origin xyz="0 0 -0.02" rpy="1.57 1.57 1.57"/>
        </visual>
        <collision>
            <geometry>
                <box size="0.0358 0.0196 0.025"/>
            </geometry>
            <origin xyz="0 0 -0.02" rpy="1.57 1.57 1.57"/>
        </collision>
    </link>
    <link name="link05">
        <visual>
            <geometry>
                <box size="0.0358 0.0196 0.025"/>
            </geometry>
            <origin xyz="0 0 -0.012" rpy="1.57 1.57 1.57"/>
        </visual>
        <collision>
            <geometry>
                <box size="0.0358 0.0196 0.025"/>
            </geometry>
            <origin xyz="0 0 -0.012" rpy="1.57 1.57 1.57"/>
        </collision>
    </link>
    <link name="link05F"/>
    <link name="link06">
        <visual>
            <geometry>
                <box size="0.0358 0.0196 0.025"/>
            </geometry>
            <origin xyz="0.005 0 -0.018" rpy="1.57 1.2 0"/>
        </visual>
        <collision>
            <geometry>
                <box size="0.0358 0.0196 0.025"/>
            </geometry>
            <origin xyz="0.005 0 -0.018" rpy="1.57 1.2 0"/>
        </collision>
    </link>
    <!--left  Leg links  x6-->
    <link name="link07">
        <visual>
            <geometry>
                <box size="0.0358 0.0196 0.025"/>
            </geometry>
            <origin xyz="0 0 -0.01" rpy="0 1.57 1.57"/>
        </visual>
        <collision>
            <geometry>
                <box size="0.0358 0.0196 0.025"/>
            </geometry>
            <origin xyz="0 0 -0.01" rpy="0 1.57 1.57"/>
        </collision>
    </link>
    <link name="link07F"/>
    <link name="link08">
        <visual>
            <geometry>
                <box size="0.0358 0.0196 0.025"/>
            </geometry>
            <origin xyz="0 0 -0.02" rpy="1.57 1.57 1.57"/>
        </visual>
        <collision>
            <geometry>
                <box size="0.0358 0.0196 0.025"/>
            </geometry>
            <origin xyz="0 0 -0.02" rpy="1.57 1.57 1.57"/>
        </collision>
    </link>
    <link name="link09">
        <visual>
            <geometry>
                <box size="0.0358 0.0196 0.025"/>
            </geometry>
            <origin xyz="0 0 -0.012" rpy="1.57 1.57 1.57"/>
        </visual>
        <collision>
            <geometry>
                <box size="0.0358 0.0196 0.025"/>
            </geometry>
            <origin xyz="0 0 -0.012" rpy="1.57 1.57 1.57"/>
        </collision>
    </link>
    <link name="link09F"/>
    <link name="link10">
        <visual>
            <geometry>
                <box size="0.0358 0.0196 0.025"/>
            </geometry>
            <origin xyz="0 0 -0.02" rpy="1.57 1.57 1.57"/>
        </visual>
        <collision>
            <geometry>
                <box size="0.0358 0.0196 0.025"/>
            </geometry>
            <origin xyz="0 0 -0.02" rpy="1.57 1.57 1.57"/>
        </collision>
    </link>
    <link name="link11">
        <visual>
            <geometry>
                <box size="0.0358 0.0196 0.025"/>
            </geometry>
            <origin xyz="0 0 -0.012" rpy="1.57 1.57 1.57"/>
        </visual>
        <collision>
            <geometry>
                <box size="0.0358 0.0196 0.025"/>
            </geometry>
            <origin xyz="0 0 -0.012" rpy="1.57 1.57 1.57"/>
        </collision>
    </link>
    <link name="link11F"/>
    <link name="link12">
        <visual>
            <geometry>
                <box size="0.0358 0.0196 0.025"/>
            </geometry>
            <origin xyz="-0.005 0 -0.018" rpy="1.57 -1.2 0"/>
        </visual>
        <collision>
            <geometry>
                <box size="0.0358 0.0196 0.025"/>
            </geometry>
            <origin xyz="-0.005 0 -0.018" rpy="1.57 -1.2 0"/>
        </collision>
    </link>

    <!--Joints Declaration-->
    <joint name="joint_base" type="fixed">
        <parent link="base_footprint"/>
        <child  link="link24"/>
        <origin xyz="0 0 0.28" rpy="0 0 0"/>
    </joint>

    <!--Body Joints       x2-->
    <joint name="joint23-24" type="revolute">
        <parent link="link24"/>
        <child  link="link23"/>
        <origin xyz="0 0 0" rpy="0 0 0"/>
        <axis xyz="0 0 1"/>
        <limit lower="-2.61799" upper="2.61799" effort="0.05" velocity="0.48"/>
    </joint>

    <joint name="joint23F-23" type="revolute">
        <parent link="link23"/>
        <child  link="link23F"/>
        <origin xyz="0 0 -0.01" rpy="0 0 0"/>
        <axis xyz="1 0 0"/>
        <limit lower="-2.61799" upper="2.61799" effort="0.05" velocity="0.48"/>
    </joint>

    <!--right Arm Joints  x5-->
    <joint name="joint17-24" type="fixed">
        <parent link="link24"/>
        <child  link="link17"/>
        <origin xyz="0.015 0 0.018" rpy="0 0 0"/>
    </joint>

    <joint name="joint16F-17" type="revolute">
        <parent link="link17"/>
        <child  link="link16F"/>
        <origin xyz="0.025 0 0" rpy="0 0 0"/>
        <axis xyz="1 0 0"/>
        <limit lower="-2.61799" upper="2.61799" effort="0.05" velocity="0.48"/>
    </joint>

    <joint name="joint16-16F" type="revolute">
        <parent link="link16F"/>
        <child  link="link16"/>
        <origin xyz="0.009 0 0.005" rpy="0 0 0"/>
        <axis xyz="0 1 0"/>
        <limit lower="-2.61799" upper="2.61799" effort="0.05" velocity="0.48"/>
    </joint>

    <joint name="joint15-16" type="fixed">
        <parent link="link16"/>
        <child  link="link15"/>
        <origin xyz="0 0 -0.011" rpy="0 0 0"/>
    </joint>

    <joint name="joint14F-15" type="revolute">
        <parent link="link15"/>
        <child  link="link14F"/>
        <origin xyz="0 0 -0.025" rpy="0 0 0"/>
        <axis xyz="0 0 1"/>
        <limit lower="-2.61799" upper="2.61799" effort="0.05" velocity="0.48"/>
    </joint>

    <joint name="joint14-14F" type="revolute">
        <parent link="link14F"/>
        <child  link="link14"/>
        <origin xyz="-0.005 0 -0.02" rpy="0 0 0"/>
        <axis xyz="0 1 0"/>
        <limit lower="-2.61799" upper="2.61799" effort="0.05" velocity="0.48"/>
    </joint>

    <joint name="joint13-14" type="fixed">
        <parent link="link14"/>
        <child  link="link13"/>
        <origin xyz="0 0 -0.015" rpy="0 0 0"/>
    </joint>

    <!--left  Arm joints  x5-->
    <joint name="joint22-24" type="fixed">
        <parent link="link24"/>
        <child  link="link22"/>
        <origin xyz="-0.015 0 0.018" rpy="0 0 0"/>
    </joint>
    
    <joint name="joint21F-22" type="revolute">
        <parent link="link22"/>
        <child  link="link21F"/>
        <origin xyz="-0.025 0 0" rpy="0 0 0"/>
        <axis xyz="1 0 0"/>
        <limit lower="-2.61799" upper="2.61799" effort="0.05" velocity="0.48"/>
    </joint>

    <joint name="joint21-21F" type="revolute">
        <parent link="link21F"/>
        <child  link="link21"/>
        <origin xyz="-0.009 0 0.005" rpy="0 0 0"/>
        <axis xyz="0 1 0"/>
        <limit lower="-2.61799" upper="2.61799" effort="0.05" velocity="0.48"/>
    </joint>

    <joint name="joint20-21" type="fixed">
        <parent link="link21"/>
        <child  link="link20"/>
        <origin xyz="0 0 -0.011" rpy="0 0 0"/>
    </joint>

    <joint name="joint19F-20" type="revolute">
        <parent link="link20"/>
        <child  link="link19F"/>
        <origin xyz="0 0 -0.025" rpy="0 0 0"/>
        <axis xyz="0 0 1"/>
        <limit lower="-2.61799" upper="2.61799" effort="0.05" velocity="0.48"/>
    </joint>

    <joint name="joint19-19F" type="revolute">
        <parent link="link19F"/>
        <child  link="link19"/>
        <origin xyz="0.005 0 -0.02" rpy="0 0 0"/>
        <axis xyz="0 1 0"/>
        <limit lower="-2.61799" upper="2.61799" effort="0.05" velocity="0.48"/>
    </joint>

    <joint name="joint18-19" type="fixed">
        <parent link="link19"/>
        <child  link="link18"/>
        <origin xyz="0 0 -0.015" rpy="0 0 0"/>
    </joint>

    <!--right Leg joints  x6-->
    <joint name="joint06-23F" type="fixed">
        <parent link="link23F"/>
        <child  link="link06"/>
        <origin xyz="0.01 -0.03 -0.015" rpy="0 0 0"/>
    </joint>

    <joint name="joint05F-06" type="revolute">
        <parent link="link06"/>
        <child  link="link05F"/>
        <origin xyz="0.01 0 -0.025" rpy="0 0 0"/>
        <axis xyz="0 1 0"/>
        <limit lower="-2.61799" upper="2.61799" effort="0.05" velocity="0.48"/>
    </joint>

    <joint name="joint05-05F" type="revolute">
        <parent link="link05F"/>
        <child  link="link05"/>
        <origin xyz="0 0.025 0" rpy="0 0 0"/>
        <axis xyz="1 0 0"/>
        <limit lower="-2.61799" upper="2.61799" effort="0.05" velocity="0.48"/>
    </joint>

    <joint name="joint04-05" type="fixed">
        <parent link="link05"/>
        <child  link="link04"/>
        <origin xyz="0 0 -0.03" rpy="0 0 0"/>
    </joint>

    <joint name="joint03F-04" type="revolute">
        <parent link="link04"/>
        <child  link="link03F"/>
        <origin xyz="0 0 -0.03" rpy="0 0 0"/>
        <axis xyz="1 0 0"/>
        <limit lower="-2.61799" upper="2.61799" effort="0.05" velocity="0.48"/>
    </joint>

    <joint name="joint03-03F" type="revolute">
        <parent link="link03F"/>
        <child  link="link03"/>
        <origin xyz="0 0 -0.038" rpy="0 0 0"/>
        <axis xyz="1 0 0"/>
        <limit lower="-2.61799" upper="2.61799" effort="0.05" velocity="0.48"/>
    </joint>

    <joint name="joint02-03" type="fixed">
        <parent link="link03"/>
        <child  link="link02"/>
        <origin xyz="0 0 -0.03" rpy="0 0 0"/>
    </joint>

    <joint name="joint01F-02" type="revolute">
        <parent link="link02"/>
        <child  link="link01F"/>
        <origin xyz="0 0 -0.03" rpy="0 0 0"/>
        <axis xyz="1 0 0"/>
        <limit lower="-2.61799" upper="2.61799" effort="0.05" velocity="0.48"/>
    </joint>

    <joint name="joint01-01F" type="revolute">
        <parent link="link01F"/>
        <child  link="link01"/>
        <origin xyz="0 -0.03 0" rpy="0 0 0"/>
        <axis xyz="0 1 0"/>
        <limit lower="-2.61799" upper="2.61799" effort="0.05" velocity="0.48"/>
    </joint>

    <!--left  Leg joints  x6-->
    <joint name="joint12-23F" type="fixed">
        <parent link="link23F"/>
        <child  link="link12"/>
        <origin xyz="-0.01 -0.03 -0.015" rpy="0 0 0"/>
    </joint>

    <joint name="joint11F-12" type="revolute">
        <parent link="link12"/>
        <child  link="link11F"/>
        <origin xyz="-0.01 0 -0.025" rpy="0 0 0"/>
        <axis xyz="0 1 0"/>
        <limit lower="-2.61799" upper="2.61799" effort="0.05" velocity="0.48"/>
    </joint>

    <joint name="joint11-11F" type="revolute">
        <parent link="link11F"/>
        <child  link="link11"/>
        <origin xyz="0 0.025 0" rpy="0 0 0"/>
        <axis xyz="1 0 0"/>
        <limit lower="-2.61799" upper="2.61799" effort="0.05" velocity="0.48"/>
    </joint>

    <joint name="joint10-11" type="fixed">
        <parent link="link11"/>
        <child  link="link10"/>
        <origin xyz="0 0 -0.03" rpy="0 0 0"/>
    </joint>

    <joint name="joint09F-10" type="revolute">
        <parent link="link10"/>
        <child  link="link09F"/>
        <origin xyz="0 0 -0.03" rpy="0 0 0"/>
        <axis xyz="1 0 0"/>
        <limit lower="-2.61799" upper="2.61799" effort="0.05" velocity="0.48"/>
    </joint>

    <joint name="joint09-09F" type="revolute">
        <parent link="link09F"/>
        <child  link="link09"/>
        <origin xyz="0 0 -0.038" rpy="0 0 0"/>
        <axis xyz="1 0 0"/>
        <limit lower="-2.61799" upper="2.61799" effort="0.05" velocity="0.48"/>
    </joint>

    <joint name="joint08-09" type="fixed">
        <parent link="link09"/>
        <child  link="link08"/>
        <origin xyz="0 0 -0.03" rpy="0 0 0"/>
    </joint>

    <joint name="joint07F-08" type="revolute">
        <parent link="link08"/>
        <child  link="link07F"/>
        <origin xyz="0 0 -0.03" rpy="0 0 0"/>
        <axis xyz="1 0 0"/>
        <limit lower="-2.61799" upper="2.61799" effort="0.05" velocity="0.48"/>
    </joint>

    <joint name="joint07-07F" type="revolute">
        <parent link="link07F"/>
        <child  link="link07"/>
        <origin xyz="0 -0.03 0" rpy="0 0 0"/>
        <axis xyz="0 1 0"/>
        <limit lower="-2.61799" upper="2.61799" effort="0.05" velocity="0.48"/>
    </joint>

</robot>